2025-09-07 12:46:59.491 | ERROR    | hcaptcha_challenger.agent.challenger:_solve_captcha:897 - ChallengeException - type=image_label_multi_select err=TimeoutError('Locator.screenshot: Timeout 30000ms exceeded.\nCall log:\n  - waiting for locator("//div[@class=\'challenge-view\']")\n')
Traceback (most recent call last):
  File "c:\Users\kingo\Desktop\Captcha3\hcaptcha\src\hcaptcha_challenger\main.py", line 141, in <module>
    asyncio.run(main())
  File "C:\Users\kingo\AppData\Local\Programs\Python\Python313\Lib\asyncio\runners.py", line 195, in run
    return runner.run(main)
  File "C:\Users\kingo\AppData\Local\Programs\Python\Python313\Lib\asyncio\runners.py", line 118, in run
    return self._loop.run_until_complete(task)
  File "C:\Users\kingo\AppData\Local\Programs\Python\Python313\Lib\asyncio\base_events.py", line 712, in run_until_complete
    self.run_forever()
  File "C:\Users\kingo\AppData\Local\Programs\Python\Python313\Lib\asyncio\base_events.py", line 683, in run_forever
    self._run_once()
  File "C:\Users\kingo\AppData\Local\Programs\Python\Python313\Lib\asyncio\base_events.py", line 2042, in _run_once
    handle._run()
  File "C:\Users\kingo\AppData\Local\Programs\Python\Python313\Lib\asyncio\events.py", line 89, in _run
    self._context.run(self._callback, *self._args)
  File "c:\Users\kingo\Desktop\Captcha3\hcaptcha\src\hcaptcha_challenger\main.py", line 117, in main
    agent = await challenge(page)
  File "c:\Users\kingo\Desktop\Captcha3\hcaptcha\src\hcaptcha_challenger\main.py", line 91, in challenge
    result = await agent.wait_for_challenge()
  File "c:\Users\kingo\Desktop\Captcha3\hcaptcha\src\hcaptcha_challenger\agent\challenger.py", line 907, in wait_for_challenge
    await asyncio.wait_for(self._solve_captcha(), timeout=self.config.EXECUTION_TIMEOUT)
  File "C:\Users\kingo\AppData\Local\Programs\Python\Python313\Lib\asyncio\tasks.py", line 507, in wait_for
    return await fut
> File "c:\Users\kingo\Desktop\Captcha3\hcaptcha\src\hcaptcha_challenger\agent\challenger.py", line 870, in _solve_captcha
    return await self.robotic_arm.challenge_image_label_select(challenge_type)
  File "c:\Users\kingo\Desktop\Captcha3\hcaptcha\src\hcaptcha_challenger\agent\challenger.py", line 649, in challenge_image_label_select
    raw, projection = await self._capture_spatial_mapping(frame_challenge, cache_key, cid)
  File "c:\Users\kingo\Desktop\Captcha3\hcaptcha\src\hcaptcha_challenger\agent\challenger.py", line 489, in _capture_spatial_mapping
    await challenge_view.screenshot(type="png", path=challenge_screenshot)
  File "C:\Users\kingo\AppData\Local\Programs\Python\Python313\Lib\site-packages\playwright\async_api\_generated.py", line 17258, in screenshot
    await self._impl_obj.screenshot(
  File "C:\Users\kingo\AppData\Local\Programs\Python\Python313\Lib\site-packages\playwright\_impl\_locator.py", line 543, in screenshot
    return await self._with_element(
  File "C:\Users\kingo\AppData\Local\Programs\Python\Python313\Lib\site-packages\playwright\_impl\_locator.py", line 112, in _with_element
    handle = await self.element_handle(timeout=timeout)
  File "C:\Users\kingo\AppData\Local\Programs\Python\Python313\Lib\site-packages\playwright\_impl\_locator.py", line 316, in element_handle
    handle = await self._frame.wait_for_selector(
  File "C:\Users\kingo\AppData\Local\Programs\Python\Python313\Lib\site-packages\playwright\_impl\_frame.py", line 369, in wait_for_selector
    await self._channel.send(
  File "C:\Users\kingo\AppData\Local\Programs\Python\Python313\Lib\site-packages\playwright\_impl\_connection.py", line 69, in send
    return await self._connection.wrap_api_call(
  File "C:\Users\kingo\AppData\Local\Programs\Python\Python313\Lib\site-packages\playwright\_impl\_connection.py", line 558, in wrap_api_call
    raise rewrite_error(error, f"{parsed_st['apiName']}: {error}") from None
playwright._impl._errors.TimeoutError: Locator.screenshot: Timeout 30000ms exceeded.
Call log:
  - waiting for locator("//div[@class='challenge-view']")

2025-09-07 12:47:04.505 | ERROR    | hcaptcha_challenger.agent.challenger:get_challenge_frame_locator:346 - Cannot find a valid challenge frame
2025-09-07 12:58:44.707 | ERROR    | hcaptcha_challenger.agent.challenger:wait_for_challenge:922 - Wait for captcha response timeout 60.0s
2025-09-07 13:03:47.766 | ERROR    | hcaptcha_challenger.agent.challenger:get_challenge_frame_locator:346 - Cannot find a valid challenge frame
